Workbook

Sheet SUMMARY
B2: DMC Thread Inventory Tracker | I2: Quick Start Guide: Add your threads to the sheet "DMC Threads - By Number" and it will auto populate in the "By Color" sheet. You can use the search function on either sheet. Want To Use "By Color" On Its Own? Hide the sheet "DMC Threads - By Color" by right clicking and selecting "hide". Then unhide "DMC Threads - By Color (2)".
B4: By Lord Libidan
C6: Yellow cells are those you can edit in the calculators.
B8: * | C8: An asterisk marks hard to find threads. These can be discontinued in some countries, or just not easy to get your hands on.
B11: Updated: | C11: 45962 | D11: Version: | E11: 18.5.5 | F11: Names: | G11: Core
F12: By Lord Libidan
B13: QUICK ACCESS BUTTONS
I15: Naming conventions: The DMC company have never officially supplied a list of names for embroidery threads (other than the 'new' 35'). This list has been complied using the most used names across retailers, resellers, designers and pattern & kit makers. If you would like a copy of the names used on the DMC website, or on a 2021 issued PDF, please contact us and we'll be able to supply!
B19: Color Charts
B23: Tools
I25: Want To Edit Sheets? That’s OK. If you see a password protected cell, or sheet, use the password "1234" to unlock them.
I29: Want To Print Sheets? Simply print "Print - By Number" and it will automatically update with the threads you own. To print blank sheets; unhide "Print - By Number - Blank"

Sheet Release Notes
A1: © Lord Libidan 2017 - 2026 | D1: Copyright covers both the excel sheet, color previews and naming conventions
A2: Version | B2: Names | C2: Release Date | D2: Additions/Corrections
A3: 18.5.4 | B3: Core | C3: 45962 | D3: Bug fix: Fixed missing cells in DMC Threads - By Color sheet
A5: 18.5.4 | B5: Core | C5: 45957 | D5: Added colors to discontinued threads sheet
D6: Added color breakout sheet for Coloris, Variation and Variegated threads
A8: 18.4.3 | B8: Core | C8: 45894 | D8: Bug fix: Corrected three colors pulling in from wrong cell in printable sheets
D9: Added 01 to 35 on thread conversion sheet
D10: Added 222 and 49 to discontinued
D11: Bug fix: Corrected order of some discontinued threads
D12: Small visual improvements
C13: sdghfgh
A14: 18.2.2 | B14: Core | C14: 45721 | D14: Added column lookup to By Color sheets
D15: Bug fix: Added lock feature to hidden By Color sheet
D16: Minor updates in Availability Checker sheet
D17: Bug fix: A few colours were bleeding over their cells
D18: Added printable sheet for By Number
A20: 18.1.9 | B20: Core | C20: 45710 | D20: Bug fix: Corrected issue with 792 on new sheet not looking up correctly
A22: 18.1.7 | B22: Core | C22: 45689 | D22: Added official Luca-S to conversion chart
D23: Added more 1920s to 1950s discontinued threads to discontinued sheet
D24: Added release notes to published version
D25: Added quick start guide and link to video on summary sheet
D26: Updated copyright tags to 2025
D27: Updated updated tags to 2025
D28: Added copyright traps
D29: Added functionality to copy "Order by Number" to "Order by Color" sheets
D30: Added some additional known discontinued threads
D31: Bug fix: Corrected alignment on tables in "Order by Color"
D32: Bug fix: Corrected fonts on both "Order by Color" sheets
A34: 17.1.2 | B34: Core | C34: 45566 | D34: Added locking functions to cells often broken and hidden sheets
D35: Added instructions for editing sheets
D36: Added more 1920s to 1950s discontinued threads to discontinued sheet
D37: Bug fix: Fixed issue with availability checker not working past row 30
A39: 16.0.7 | B39: Core | C39: 45536 | D39: Updated copyright tags to 2024
D40: Bug fix: Floss use estimator confused on line 27, doubling required skeins
D41: Added Limited Edition and Winnie The Pooh Threads
A43: 16.0.5 | B43: Core | C43: 45505 | D43: Added links to more information on discontinued & hard-to-find sheet
D44: Added partially discontinued threads to discontinued & hard-to-find sheet
D45: Added new copyright traps
D46: Updated naming conventions block to offer 'official' DMC names where requested
D47: Added "Representive" tag to some metalic colors
...

Sheet DMC Threads - By Number
B2: SEARCH | C2: Name | D2: Owned
B3: 310 | C3: =VLOOKUP(B3,Sheet1!A1:C815,2,FALSE) -> Black | D3: =VLOOKUP(B3,Sheet1!A1:C815,3,FALSE) -> 0
G4: By Lord Libidan
B5: Number | C5: Name | D5: Color | E5: Owned | G5: Number | H5: Name | I5: Color | J5: Owned | L5: Number | M5: Name | N5: Color | O5: Owned | Q5: Number | R5: Name | S5: Color | T5: Owned | V5: Number | W5: Name | X5: Color | Y5: Owned | AA5: Number | AB5: Name | AC5: Color | AD5: Owned | AF5: Number | AG5: Name | AH5: Color | AI5: Owned | AK5: Number | AL5: Name | AM5: Color | AN5: Owned | AP5: Number | AQ5: Name | AR5: Color | AS5: Owned | AU5: Number | AV5: Name | AW5: Color | AX5: Owned | AZ5: Number | BA5: Name | BB5: Color | BC5: Owned | BE5: Number | BF5: Name | BG5: Color | BH5: Owned | BJ5: Number | BK5: Name | BL5: Color | BM5: Owned | BO5: Discontinued/Hard-To-Find Variegated Threads | BT5: Discontinued/Hard-To-Find Metallic Threads
B6: Ecru | C6: Ecru/off-white | G6: 300 | H6: Mahogany - Very Dark | L6: 517 | M6: Wedgewood - Dark | Q6: 739 | R6: Tan - Ultra Very Light | V6: 890 | W6: Pistachio Green - Ultra Dark | AA6: 988 | AB6: Forest Green - Medium | AF6: 3752 | AG6: Antique Blue - Very Light | AK6: 3845 | AL6: Bright Turquoise - Medium | AP6: E146* | AQ6: Metallic - Tropical Delight | AU6: 4120 | AV6: Variations - Tropical Sunset | AZ6: 4500 | BA6: Coloris - Columbine Gardens | BE6: S5200 | BF6: Satin - Snow White | BJ6: 30300 | BK6: Discontinued Rayon - Very Dark Mahogany | BO6: Number | BP6: Name | BQ6: Color | BR6: Owned | BT6: Number | BU6: Name | BV6: Color | BW6: Owned
B7: Blanc^ | C7: White | G7: 301 | H7: Mahogany - Medium | L7: 518 | M7: Wedgewood - Light | Q7: 740 | R7: Tangerine | V7: 891 | W7: Carnation - Dark | AA7: 989 | AB7: Forest Green | AF7: 3753 | AG7: Antique Blue - Ultra Very Light | AK7: 3846 | AL7: Bright Turquoise - Light | AP7: E148* | AQ7: Metallic - Purple Essence | AU7: 4124 | AV7: Variations - Bonfire | AZ7: 4501 | BA7: Coloris - Wildflowers | BE7: S211 | BF7: Satin - Lavender | BJ7: 30301 | BK7: Discontinued Rayon - Medium Mahogany | BO7: 48* | BP7: Discontinued Variegated - Baby Pink | BT7: 5269* | BU7: Discontinued Metallic - Green Emerald
B8: White^ | C8: White | G8: 304 | H8: Red - Medium | L8: 519 | M8: Sky Blue | Q8: 741 | R8: Tangerine - Medium | V8: 892 | W8: Carnation - Medium | AA8: 991 | AB8: Aquamarine - Dark | AF8: 3755 | AG8: Baby Blue | AK8: 3847 | AL8: Teal Green - Dark | AP8: E150* | AQ8: Metallic - Deep Water Blue | AU8: 4126 | AV8: Variations - Desert Canyon | AZ8: 4502 | BA8: Coloris - Camelia | BE8: S307 | BF8: Satin - Lemon | BJ8: 30307 | BK8: Discontinued Rayon - Lemon | BO8: 49* | BP8: Discontinued Variegated - Burnt Sage | BT8: 5270* | BU8: Discontinued Metallic - Dark Red Ruby
B9: B5200 | C9: Snow White | G9: 307 | H9: Lemon | L9: 520 | M9: Fern Green - Dark | Q9: 742 | R9: Tangerine - Light | V9: 893 | W9: Carnation - Light | AA9: 992 | AB9: Aquamarine - Light | AF9: 3756 | AG9: Baby Blue - Light | AK9: 3848 | AL9: Teal Green - Medium | AP9: E152* | AQ9: Metallic - Pink Shimmer | AU9: 4128 | AV9: Variations - Gold Coast | AZ9: 4503 | BA9: Coloris - Wisteria | BE9: S310 | BF9: Satin - Black | BJ9: 30310 | BK9: Discontinued Rayon - Black | BO9: 51* | BP9: Discontinued Variegated - Burnt Orange | BT9: 5272* | BU9: Discontinued Metallic - White
B10: 1 | C10: White Tin | G10: 309 | H10: Rose - Dark | L10: 522 | M10: Fern Green | Q10: 743 | R10: Yellow - Medium | V10: 894 | W10: Carnation - Very Light | AA10: 993 | AB10: Aquamarine - Very Light | AF10: 3760 | AG10: Wedgewood - Medium | AK10: 3849 | AL10: Teal Green - Light | AP10: E154* | AQ10: Metallic - Opalescent Rays | AU10: 4130 | AV10: Variations - Chilean Sunset | AZ10: 4504 | BA10: Coloris - Hydrangea | BE10: S321 | BF10: Satin - Red | BJ10: 30326 | BK10: Discontinued Rayon - Very Dark Rose | BO10: 52* | BP10: Discontinued Variegated - Violet | BT10: 5279* | BU10: Discontinued Metallic - Copper
B11: 2 | C11: Tin | G11: 310 | H11: Black | L11: 523 | M11: Fern Green - Light | Q11: 744 | R11: Yellow - Pale | V11: 895 | W11: Hunter Green - Very Dark | AA11: 995 | AB11: Electric Blue - Dark | AF11: 3761 | AG11: Sky Blue - Light | AK11: 3850 | AL11: Bright Green - Dark | AP11: E155 | AQ11: Metallic - Amethyst | AU11: 4140 | AV11: Variations - Driftwood | AZ11: 4505 | BA11: Coloris - Heather | BE11: S326 | BF11: Satin - Rose | BJ11: 30336 | BK11: Discontinued Rayon - Navy Blue | BO11: 53* | BP11: Discontinued Variegated - Steel Gray | BT11: 5282* | BU11: Discontinued Metallic - Light Gold
B12: 3 | C12: Tin - Medium | G12: 311 | H12: Blue - Medium | L12: 524 | M12: Fern Green - Very Light | Q12: 745 | R12: Yellow - Light Pale | V12: 898 | W12: Coffee Brown - Very Dark | AA12: 996 | AB12: Electric Blue - Medium | AF12: 3765 | AG12: Peacock Blue - Very Dark | AK12: 3851 | AL12: Bright Green - Light | AP12: E168 | AQ12: Metallic - Silver | AU12: 4145 | AV12: Variations - Sandune | AZ12: 4506 | BA12: Coloris - Spring | BE12: S336* | BF12: Satin - Blue | BJ12: 30351 | BK12: Discontinued Rayon - Coral | BO12: 57* | BP12: Discontinued Variegated - Red | BT12: 5283* | BU12: Discontinued Metallic - Silver
B13: 4 | C13: Tin - Dark | G13: 312 | H13: Baby Blue - Very Dark | L13: 535 | M13: Ash Gray - Very Light | Q13: 746 | R13: Off White | V13: 899 | W13: Rose - Medium | AA13: 3011 | AB13: Khaki Green - Dark | AF13: 3766 | AG13: Peacock Blue - Light | AK13: 3852 | AL13: Straw - Very Dark | AP13: E211 | AQ13: Metallic - Lilac | AU13: 4150 | AV13: Variations - Desert Sand | AZ13: 4507 | BA13: Coloris - Bouginvillea | BE13: S351 | BF13: Satin - Coral | BJ13: 30352 | BK13: Discontinued Rayon - Light Coral | BO13: 61* | BP13: Discontinued Variegated - Topaz | BT13: 5284* | BU13: Discontinued Metallic - Dark Gold
B14: 5 | C14: Driftwood - Light | G14: 315 | H14: Antique Mauve - Medium Dark | L14: 543 | M14: Beige Brown - Ultra Very Light | Q14: 747 | R14: Sky Blue - Very Light | V14: 900 | W14: Burnt Orange - Dark | AA14: 3012 | AB14: Khaki Green - Medium | AF14: 3768 | AG14: Gray Green - Dark | AK14: 3853 | AL14: Autumn Gold - Dark | AP14: E301 | AQ14: Metallic - Copper | AU14: 4160 | AV14: Variations - Glistening Pearl | AZ14: 4508 | BA14: Coloris - Frosted Countryside | BE14: S352 | BF14: Satin - Coral Light | BJ14: 30434 | BK14: Discontinued Rayon - Light Brown | BO14: 62* | BP14: Discontinued Variegated - Dusty Rose | BT14: 5287* | BU14: Discontinued Metallic - Titanium
B15: 6 | C15: Driftwood - Medium Light | G15: 316 | H15: Antique Mauve - Medium | L15: 550 | M15: Violet - Very Dark | Q15: 754 | R15: Peach - Light | V15: 902 | W15: Garnet - Very Dark | AA15: 3013 | AB15: Khaki Green - Light | AF15: 3770 | AG15: Tawny - Very Light | AK15: 3854 | AL15: Autumn Gold - Medium | AP15: E310 | AQ15: Metallic - Ebony | AU15: 4170 | AV15: Variations - Whispering Wind | AZ15: 4509 | BA15: Coloris - Granite Coast | BE15: S367 | BF15: Satin - Pistachio Green | BJ15: 30435 | BK15: Discontinued Rayon - Very Light Brown | BO15: 67* | BP15: Discontinued Variegated - Baby Blue | BT15: 5288* | BU15: Discontinued Metallic - Pink Amethyst
B16: 7 | C16: Driftwood | G16: 317 | H16: Pewter Gray | L16: 552 | M16: Violet - Medium | Q16: 758 | R16: Terra Cotta - Very Light | V16: 904 | W16: Parrot Green - Very Dark | AA16: 3021 | AB16: Brown Gray - Very Dark | AF16: 3771 | AG16: Peach - Dark | AK16: 3855 | AL16: Autumn Gold - Light | AP16: E316 | AQ16: Metallic - Pink Amethyst | AU16: 4180 | AV16: Variations - Rose Petals | AZ16: 4510 | BA16: Coloris - Maple | BE16: S414* | BF16: Satin - Steel Grey | BJ16: 30469 | BK16: Discontinued Rayon - Avocado Green | BO16: 69* | BP16: Discontinued Variegated - Terra Cotta | BT16: 5289* | BU16: Discontinued Metallic - Purple Ruby
B17: 8 | C17: Driftwood - Dark | G17: 318 | H17: Steel Gray - Light | L17: 553 | M17: Violet | Q17: 760 | R17: Salmon | V17: 905 | W17: Parrot Green - Dark | AA17: 3022 | AB17: Brown Gray - Medium | AF17: 3772 | AG17: Desert Sand - Very Dark | AK17: 3856 | AL17: Mahogany - Ultra Very Light | AP17: E317 | AQ17: Metallic - Titanium | AU17: 4190 | AV17: Variations - Ocean Coral | AZ17: 4511 | BA17: Coloris - Indian Summer | BE17: S415 | BF17: Satin - Pearl Grey | BJ17: 30501 | BK17: Discontinued Rayon - Dark Blue Green | BO17: 75* | BP17: Discontinued Variegated - Cranberry | BT17: 5290* | BU17: Discontinued Metallic - Light Blue Sapphire
B18: 9 | C18: Cocoa - Very Dark | G18: 319 | H18: Pistachio Green - Very Dark | L18: 554 | M18: Violet - Light | Q18: 761 | R18: Salmon - Light | V18: 906 | W18: Parrot Green - Medium | AA18: 3023 | AB18: Brown Gray - Light | AF18: 3773* | AG18: Desert Sand - Medium | AK18: 3857 | AL18: Rosewood - Dark | AP18: E321 | AQ18: Metallic - Red Ruby | AU18: 4200 | AV18: Variations - Wild Fire | AZ18: 4512 | BA18: Coloris - States | BE18: S434* | BF18: Satin - Brown | BJ18: 30503 | BK18: Discontinued Rayon - Medium Blue Green | BO18: 90* | BP18: Discontinued Variegated - Yellow | BT18: 5290* | BU18: Discontinued Metallic - Royal Blue
B19: 10 | C19: Tender Green - Very Light | G19: 320 | H19: Pistachio Green - Medium | L19: 561 | M19: Jade - Very Dark | Q19: 762 | R19: Pearl Gray - Very Light | V19: 907 | W19: Parrot Green - Light | AA19: 3024 | AB19: Brown Gray - Very Light | AF19: 3774 | AG19: Desert Sand - Very Light | AK19: 3858 | AL19: Rosewood - Medium | AP19: E334 | AQ19: Metallic - Blue Topaz | AU19: 4210 | AV19: Variations - Radiant Ruby | AZ19: 4513 | BA19: Coloris - London | BE19: S469* | BF19: Satin - Avacado Green | BJ19: 30504 | BK19: Discontinued Rayon - Light Blue Green | BO19: 91* | BP19: Discontinued Variegated - Turquoise | BT19: E131* | BU19: Discontinued Metallic - Carnivale Fun | BV19: Representative
B20: 11 | C20: Tender Green - Light | G20: 321 | H20: Red | L20: 562 | M20: Jade - Medium | Q20: 772 | R20: Yellow Green - Very Light | V20: 909 | W20: Emerald Green - Very Dark | AA20: 3031 | AB20: Mocha Brown - Very Dark | AF20: 3776 | AG20: Mahogany - Light | AK20: 3859 | AL20: Rosewood - Light | AP20: E415 | AQ20: Metallic - Pewter | AU20: 4215 | AV20: Variations - Northern Lights | AZ20: 4514 | BA20: Coloris - Venice | BE20: S471 | BF20: Satin - Avocado Green Very Light | BJ20: 30543 | BK20: Discontinued Rayon - Ultra Very Light Beige Brown | BO20: 92* | BP20: Discontinued Variegated - Avocado | BT20: E133* | BU20: Discontinued Metallic - Midnight Madness | BV20: Representative
B21: 12 | C21: Tender Green | G21: 322 | H21: Baby Blue | L21: 563 | M21: Jade - Light | Q21: 775 | R21: Baby Blue - Very Light | V21: 910 | W21: Emerald Green - Dark | AA21: 3032 | AB21: Mocha Brown - Medium | AF21: 3777 | AG21: Terra Cotta - Very Dark | AK21: 3860 | AL21: Cocoa | AP21: E436 | AQ21: Metallic - Golden Oak | AU21: 4220 | AV21: Variations - Lavender Fields | AZ21: 4515 | BA21: Coloris - Paris | BE21: S472 | BF21: Satin - Avocado Green Ultra Light | BJ21: 30550 | BK21: Discontinued Rayon - Very Dark Violet | BO21: 93* | BP21: Discontinued Variegated - Cornflower Blue | BT21: E136* | BU21: Discontinued Metallic - Emerald Isle | BV21: Representative
B22: 13 | C22: Nile Green - Medium Light | G22: 326 | H22: Rose - Very Dark | L22: 564 | M22: Jade - Very Light | Q22: 776* | R22: Pink - Medium | V22: 911 | W22: Emerald Green - Medium | AA22: 3033 | AB22: Mocha Brown - Very Light | AF22: 3778 | AG22: Terra Cotta - Light | AK22: 3861 | AL22: Cocoa - Light | AP22: E677 | AQ22: Metallic - White Gold | AU22: 4230 | AV22: Variations - Crystal Water | AZ22: 4516 | BA22: Coloris - Black Forest | BE22: S501* | BF22: Satin - Blue Green Dark | BJ22: 30552 | BK22: Discontinued Rayon - Medium Violet | BO22: 94* | BP22: Discontinued Variegated - Khaki Green | BT22: E138* | BU22: Discontinued Metallic - Opalescent Rays | BV22: Representative
B23: 14 | C23: Apple Green - Pale | G23: 327 | H23: Violet | L23: 580 | M23: Moss Green - Dark | Q23: 777 | R23: Red - Deep | V23: 912 | W23: Emerald Green - Light | AA23: 3041 | AB23: Antique Violet - Medium | AF23: 3779 | AG23: Terra Cotta - Ultra Very Light | AK23: 3862 | AL23: Mocha Beige - Dark | AP23: E699 | AQ23: Metallic - Green Emerald | AU23: 4235 | AV23: Variations - Arctic Sea | AZ23: 4517 | BA23: Coloris - Elves | BE23: S504 | BF23: Satin - Blue Green | BJ23: 30553 | BK23: Discontinued Rayon - Violet | BO23: 95* | BP23: Discontinued Variegated - Purple | BT23: E140* | BU23: Discontinued Metallic - Tropical Delight | BV23: Representative
B24: 15 | C24: Apple Green | G24: 333 | H24: Blue Violet - Very Dark | L24: 581 | M24: Moss Green | Q24: 778 | R24: Antique Mauve - Very Light | V24: 913 | W24: Nile Green - Medium | AA24: 3042 | AB24: Antique Violet - Light | AF24: 3781 | AG24: Mocha Brown - Dark | AK24: 3863 | AL24: Mocha Beige - Medium | AP24: E703 | AQ24: Metallic - Light Green Emerald | AU24: 4240 | AV24: Variations - Mid Summer Night | AZ24: 4518 | BA24: Coloris - Cottage | BE24: S550 | BF24: Satin - Violet Dark | BJ24: 30554 | BK24: Discontinued Rayon - Light Violet | BO24: 99* | BP24: Discontinued Variegated - Mauve | BT24: E141* | BU24: Discontinued Metallic - Holiday Sparkle | BV24: Representative
B25: 16 | C25: Chartreuse - Light | G25: 334 | H25: Baby Blue - Medium | L25: 597 | M25: Turquoise | Q25: 779 | R25: Brown | V25: 915 | W25: Plum - Dark | AA25: 3045 | AB25: Yellow Beige - Dark | AF25: 3782 | AG25: Mocha Brown - Light | AK25: 3864 | AL25: Mocha Beige - Light | AP25: E718 | AQ25: Metallic - Pink Garnet | AZ25: 4519 | BA25: Coloris - Jingle Bells | BE25: S552 | BF25: Satin - Violet Medium | BJ25: 30580 | BK25: Discontinued Rayon - Dark Moss Green | BO25: 101* | BP25: Discontinued Variegated - Spring Green | BT25: E144* | BU25: Discontinued Metallic - Majestic Metals | BV25: Representative
B26: 17 | C26: Yellow Plum - Light | G26: 335 | H26: Rose | L26: 598 | M26: Turquoise - Light | Q26: 780 | R26: Topaz - Ultra Very Dark | V26: 917 | W26: Plum - Medium | AA26: 3046 | AB26: Yellow Beige - Medium | AF26: 3787 | AG26: Brown Gray - Dark | AK26: 3865 | AL26: Winter White | AP26: E746 | AQ26: Metallic - Cream | AZ26: 4520 | BA26: Coloris - Christmas Story | BE26: S553* | BF26: Satin - Violet | BJ26: 30601 | BK26: Discontinued Rayon - Dark Cranberry | BO26: 102* | BP26: Discontinued Variegated - Dark Violet | BT26: E146* | BU26: Discontinued Metallic - Caribbean Ripples | BV26: Representative
B27: 18 | C27: Yellow Plum | G27: 336 | H27: Blue | L27: 600 | M27: Cranberry - Very Dark | Q27: 781* | R27: Topaz - Very Dark | V27: 918 | W27: Red Copper - Dark | AA27: 3047 | AB27: Yellow Beige - Light | AF27: 3790 | AG27: Beige Gray - Ultra Dark | AK27: 3866 | AL27: Mocha Brown - Ultra Very Light | AP27: E747 | AQ27: Metallic - Baby Blue | AZ27: 4521 | BA27: Coloris - Wide Open Spaces | BE27: S601 | BF27: Satin - Cranberry Dark | BJ27: 30602 | BK27: Discontinued Rayon - Medium Cranberry | BO27: 103* | BP27: Discontinued Variegated - Royal Blue | BT27: E148* | BU27: Discontinued Metallic - Purple Essence | BV27: Representative
B28: 19 | C28: Autumn Gold - Medium Light | G28: 340 | H28: Blue Violet - Medium | L28: 601 | M28: Cranberry - Dark | Q28: 782 | R28: Topaz - Dark | V28: 919 | W28: Red Copper | AA28: 3051 | AB28: Green Gray - Dark | AF28: 3799 | AG28: Pewter Gray - Very Dark | AK28: 3880* | AL28: Shell Pink - Light | AP28: E815 | AQ28: Metallic - Dark Red Ruby | AZ28: 4522 | BA28: Coloris - Canadian Night | BE28: S602 | BF28: Satin - Cranberry | BJ28: 30606 | BK28: Discontinued Rayon - Bright Orange Red | BO28: 104* | BP28: Discontinued Variegated - Lemon | BT28: E150* | BU28: Discontinued Metallic - Deep Water Blue | BV28: Representative
B29: 20 | C29: Shrimp | G29: 341 | H29: Blue Violet - Light | L29: 602 | M29: Cranberry - Medium | Q29: 783 | R29: Topaz - Medium | V29: 920 | W29: Copper - Medium | AA29: 3052 | AB29: Green Gray - Medium | AF29: 3801 | AG29: Melon - Very Dark | AK29: 3881* | AL29: Green - Light | AP29: E818 | AQ29: Metallic - Soft Pink | AZ29: 4523 | BA29: Coloris - North Wind | BE29: S606 | BF29: Satin - Orange Red | BJ29: 30666 | BK29: Discontinued Rayon - Bright Red | BO29: 105* | BP29: Discontinued Variegated - Tan Brown | BT29: E152* | BU29: Discontinued Metallic - Pink Shimmer | BV29: Representative
B30: 21 | C30: Alizarian - Light | G30: 347 | H30: Salmon - Very Dark | L30: 603 | M30: Cranberry - Light Medium | Q30: 791 | R30: Cornflower Blue - Very Dark | V30: 921 | W30: Copper | AA30: 3053 | AB30: Green Gray | AF30: 3802 | AG30: Antique Mauve - Very Dark | AK30: 3882* | AL30: Beige Brown - Dark | AP30: E825 | AQ30: Metallic - Blue Sapphire | AZ30: CBlanc | BA30: Étoile - White | BE30: S666* | BF30: Satin - Red Bright | BJ30: 30676 | BK30: Discontinued Rayon - Light Old Gold | BO30: 106* | BP30: Discontinued Variegated - Coral | BT30: E154* | BU30: Discontinued Metallic - All That Jazz | BV30: Representative
B31: 22 | C31: Alizarian | G31: 349 | H31: Coral - Dark | L31: 604 | M31: Cranberry - Light | Q31: 792 | R31: Cornflower Blue - Dark | V31: 922 | W31: Copper - Light | AA31: 3064 | AB31: Desert Sand | AF31: 3803 | AG31: Mauve - Dark | AK31: 3883* | AL31: Orange Spice - Light | AP31: E898 | AQ31: Metallic - Dark Oak | AZ31: CEcru | BA31: Étoile - Ecru/off-white | BE31: S676* | BF31: Satin - Old Gold | BJ31: 30702 | BK31: Discontinued Rayon - Kelly Green | BO31: 107* | BP31: Discontinued Variegated - Carnation | BT31: E170* | BU31: Discontinued Metallic - White Silver
B32: 23 | C32: Apple Blossom | G32: 350 | H32: Coral - Medium | L32: 605 | M32: Cranberry - Very Light | Q32: 793 | R32: Cornflower Blue - Medium | V32: 924 | W32: Gray Green - Very Dark | AA32: 3072 | AB32: Beaver Gray - Very Light | AF32: 3804 | AG32: Cyclamen Pink - Dark | AK32: 3884* | AL32: Ash Gray - Very Light | AP32: E966 | AQ32: Metallic - Lime | AZ32: C310 | BA32: Étoile - Black | BE32: S700 | BF32: Satin - Green | BJ32: 30712 | BK32: Discontinued Rayon - Cream | BO32: 108* | BP32: Discontinued Variegated - Yellow Orange | BT32: E305* | BU32: Discontinued Metallic - Titanium
B33: 24 | C33: White Lavender | G33: 351 | H33: Coral | L33: 606 | M33: Orange-red - Bright | Q33: 794 | R33: Cornflower Blue - Light | V33: 926 | W33: Gray Green - Medium | AA33: 3078 | AB33: Golden Yellow - Very Light | AF33: 3805 | AG33: Cyclamen Pink | AK33: 3885* | AL33: Baby Blue - Very Dark | AP33: E967 | AQ33: Metallic - Soft Peach | AZ33: C318 | BA33: Étoile - Steel Gray - Light | BE33: S702* | BF33: Satin - Kelly Green | BJ33: 30726 | BK33: Discontinued Rayon - Light Topaz | BO33: 111* | BP33: Discontinued Variegated - Mustard | BT33: E3821* | BU33: Discontinued Metallic - Straw Gold
B34: 25 | C34: Lavender - Ultra Light | G34: 352 | H34: Coral - Light | L34: 608 | M34: Orange - Bright | Q34: 796 | R34: Royal Blue - Dark | V34: 927 | W34: Gray Green - Light | AA34: 3325 | AB34: Baby Blue - Light | AF34: 3806 | AG34: Cyclamen Pink - Light | AK34: 3886* | AL34: Mauve - Very Dark | AP34: E3685 | AQ34: Metallic - Rosewood | AZ34: C321 | BA34: Étoile - Red | BE34: S712* | BF34: Satin - Cream | BJ34: 30742 | BK34: Discontinued Rayon - Light Tangerine | BO34: 112* | BP34: Discontinued Variegated - Salmon | BT34: E3868* | BU34: Discontinued Metallic - Light Silver
B35: 26 | C35: Lavender - Pale | G35: 353 | H35: Peach | L35: 610 | M35: Drab Brown - Dark | Q35: 797 | R35: Royal Blue | V35: 928 | W35: Gray Green - Very Light | AA35: 3326 | AB35: Rose - Light | AF35: 3807 | AG35: Cornflower Blue | AK35: 3887* | AL35: Lavender - Very Dark | AP35: E3747 | AQ35: Metallic - Sky Blue | AZ35: C415 | BA35: Étoile - Pearl Grey | BE35: S726* | BF35: Satin - Topaz | BJ35: 30744 | BK35: Discontinued Rayon - Pale Yellow | BO35: 113* | BP35: Discontinued Variegated - Wedgewood Blue | BT35: E3870* | BU35: Discontinued Metallic - Bronze Gold
B36: 27 | C36: White Violet | G36: 355 | H36: Terra Cotta - Dark | L36: 611 | M36: Drab Brown | Q36: 798 | R36: Delft Blue - Dark | V36: 930 | W36: Antique Blue - Dark | AA36: 3328 | AB36: Salmon - Dark | AF36: 3808 | AG36: Turquoise - Ultra Very Dark | AK36: 3888* | AL36: Antique Violet - Dark | AP36: E3821 | AQ36: Metallic - Light Gold | AZ36: C433 | BA36: Étoile - Brown - Medium | BE36: S738* | BF36: Satin - Tan Dark | BJ36: 30797 | BK36: Discontinued Rayon - Royal Blue | BO36: 114* | BP36: Discontinued Variegated - Lime Green | BT36: SPBlanc* | BU36: Discontinued Secret Perfume - Lily Of The Valley
B37: 28 | C37: Eggplant - Medium Light | G37: 356 | H37: Terra Cotta - Medium | L37: 612 | M37: Drab Brown - Light | Q37: 799 | R37: Delft Blue - Medium | V37: 931 | W37: Antique Blue - Medium | AA37: 3340 | AB37: Apricot - Medium | AF37: 3809 | AG37: Turquoise - Very Dark | AK37: 3889* | AL37: Lemon - Light | AP37: E3837 | AQ37: Metallic - Purple Ruby | AZ37: C436 | BA37: Étoile - Tan | BE37: S739* | BF37: Satin - Tan | BJ37: 30798 | BK37: Discontinued Rayon - Dark Delft Blue | BO37: 115* | BP37: Discontinued Variegated - Garnet | BT37: SP321* | BU37: Discontinued Secret Perfume - Strawberry
B38: 29 | C38: Eggplant | G38: 367 | H38: Pistachio Green - Dark | L38: 613 | M38: Drab Brown - Very Light | Q38: 800 | R38: Delft Blue - Pale | V38: 932 | W38: Antique Blue - Light | AA38: 3341 | AB38: Apricot | AF38: 3810 | AG38: Turquoise - Dark | AK38: 3890* | AL38: Peacock Blue - Light | AP38: E3843 | AQ38: Metallic - Light Blue Sapphire | AZ38: C444 | BA38: Étoile - Lemon - Dark | BE38: S741 | BF38: Satin - Tangerine | BJ38: 30799 | BK38: Discontinued Rayon - Medium Delft Blue | BO38: 116* | BP38: Discontinued Variegated - Cyclamen Pink | BT38: SP340* | BU38: Discontinued Secret Perfume - Lavender
B39: 30 | C39: Blueberry - Medium Light | G39: 368 | H39: Pistachio Green - Light | L39: 632 | M39: Desert Sand - Ultra Very Dark | Q39: 801 | R39: Coffee Brown - Dark | V39: 934 | W39: Avocado Green - BLACK | AA39: 3345 | AB39: Hunter Green - Dark | AF39: 3811 | AG39: Turquoise - Very Light | AK39: 3891* | AL39: Electric Blue - Dark | AP39: E3849 | AQ39: Metallic - Aquamarine Blue | AZ39: C471 | BA39: Étoile - Avocado Green - Very Light | BE39: S744* | BF39: Satin - Yellow | BJ39: 30813 | BK39: Discontinued Rayon - Light Blue | BO39: 121* | BP39: Discontinued Variegated - Delft Blue | BT39: SP603* | BU39: Discontinued Secret Perfume - Rose
B40: 31 | C40: Blueberry | G40: 369 | H40: Pistachio Green - Very Light | L40: 640 | M40: Beige Gray - Very Dark | Q40: 803 | R40: Blue - Deep | V40: 935 | W40: Avocado Green - Dark | AA40: 3346 | AB40: Hunter Green | AF40: 3812 | AG40: Seagreen - Very Dark | AK40: 3892* | AL40: Tangerine | AP40: E3852 | AQ40: Metallic - Dark Gold | AZ40: C519 | BA40: Étoile - Sky Blue | BE40: S745* | BF40: Satin - Yellow Pale | BJ40: 30814 | BK40: Discontinued Rayon - Dark Garnet | BO40: 122* | BP40: Discontinued Variegated - Olive Green | BT40: SP703* | BU40: Discontinued Secret Perfume - Apple
B41: 32 | C41: Blueberry - Dark | G41: 370 | H41: Mustard - Medium | L41: 642 | M41: Beige Gray - Dark | Q41: 806* | R41: Peacock Blue - Dark | V41: 936 | W41: Avocado Green - Very Dark | AA41: 3347 | AB41: Yellow Green - Medium | AF41: 3813 | AG41: Blue Green - Light | AK41: 3893* | AL41: Beige Brown - Ultra Very Light | AP41: E980 | AQ41: Neon - Neon Yellow | AZ41: C550 | BA41: Étoile - Violet - Very Dark | BE41: S762* | BF41: Satin - Pearl Grey | BJ41: 30818 | BK41: Discontinued Rayon - Baby Pink | BO41: 123* | BP41: Discontinued Variegated - Teal | BT41: SP726* | BU41: Discontinued Secret Perfume - Lemon
...

Sheet Sheet1
A1: Ecru | B1: Ecru/off-white | C1: ='DMC Threads - By Number'!E6 -> 0 | D1: 19
A2: Blanc | B2: White | C2: ='DMC Threads - By Number'!E7 -> 0 | D2: 20
A3: White | B3: White | C3: ='DMC Threads - By Number'!E8 -> 0 | D3: 20
A4: B5200 | B4: Snow White | C4: ='DMC Threads - By Number'!E9 -> 0 | D4: 20
A5: 1 | B5: White Tin | C5: ='DMC Threads - By Number'!E10 -> 0 | D5: 20
A6: 2 | B6: Tin | C6: ='DMC Threads - By Number'!E11 -> 0 | D6: 20
A7: 3 | B7: Tin - Medium | C7: ='DMC Threads - By Number'!E12 -> 0 | D7: 20
A8: 4 | B8: Tin - Dark | C8: ='DMC Threads - By Number'!E13 -> 0 | D8: 20
A9: 5 | B9: Driftwood - Light | C9: ='DMC Threads - By Number'!E14 -> 0 | D9: 19
A10: 6 | B10: Driftwood - Medium Light | C10: ='DMC Threads - By Number'!E15 -> 0 | D10: 19
A11: 7 | B11: Driftwood | C11: ='DMC Threads - By Number'!E16 -> 0 | D11: 19
A12: 8 | B12: Driftwood - Dark | C12: ='DMC Threads - By Number'!E17 -> 0 | D12: 19
A13: 9 | B13: Cocoa - Very Dark | C13: ='DMC Threads - By Number'!E18 -> 0 | D13: 18
A14: 10 | B14: Tender Green - Very Light | C14: ='DMC Threads - By Number'!E19 -> 0 | D14: 12
A15: 11 | B15: Tender Green - Light | C15: ='DMC Threads - By Number'!E20 -> 0 | D15: 12
A16: 12 | B16: Tender Green | C16: ='DMC Threads - By Number'!E21 -> 0 | D16: 12
... A67: 225 | B67: Shell Pink - Ultra Very Light | C67: ='DMC Threads - By Number'!E72 -> 0 | D67: 16
A68: 300 | B68: Mahogany - Very Dark | C68: ='DMC Threads - By Number'!J6 -> 0 | D68: 16
A69: 301 | B69: Mahogany - Medium | C69: ='DMC Threads - By Number'!J7 -> 0 | D69: 16
A70: 304 | B70: Red - Medium | C70: ='DMC Threads - By Number'!J8 -> 0 | D70: 1
A71: 307 | B71: Lemon | C71: ='DMC Threads - By Number'!J9 -> 0 | D71: 15
A72: 309 | B72: Rose - Dark | C72: ='DMC Threads - By Number'!J10 -> 0 | D72: 2
A73: 310 | B73: Black | C73: ='DMC Threads - By Number'!J11 -> 0 | D73: 20
A74: 311 | B74: Blue - Medium | C74: ='DMC Threads - By Number'!J12 -> 0 | D74: 8
A75: 312 | B75: Baby Blue - Very Dark | C75: ='DMC Threads - By Number'!J13 -> 0 | D75: 7
A76: 315 | B76: Antique Mauve - Medium Dark | C76: ='DMC Threads - By Number'!J14 -> 0 | D76: 4
A77: 316 | B77: Antique Mauve - Medium | C77: ='DMC Threads - By Number'!J15 -> 0 | D77: 4
A78: 317 | B78: Pewter Gray | C78: ='DMC Threads - By Number'!J16 -> 0 | D78: 20
A79: 318 | B79: Steel Gray - Light | C79: ='DMC Threads - By Number'!J17 -> 0 | D79: 20
... A132: 503 | B132: Blue Green - Medium | C132: ='DMC Threads - By Number'!J70 -> 0 | D132: 9
A133: 504 | B133: Blue Green - Very Light | C133: ='DMC Threads - By Number'!J71 -> 0 | D133: N/A
A134: 505 | B134: Grass Green - Dark | C134: ='DMC Threads - By Number'!J72 -> 0 | D134: 9
A135: 517 | B135: Wedgewood - Dark | C135: ='DMC Threads - By Number'!O6 -> 0 | D135: 8
A136: 518 | B136: Wedgewood - Light | C136: ='DMC Threads - By Number'!O7 -> 0 | D136: 8
A137: 519 | B137: Sky Blue | C137: ='DMC Threads - By Number'!O8 -> 0 | D137: 8
A138: 520 | B138: Fern Green - Dark | C138: ='DMC Threads - By Number'!O9 -> 0 | D138: 12
A139: 522 | B139: Fern Green | C139: ='DMC Threads - By Number'!O10 -> 0 | D139: 12
A140: 523 | B140: Fern Green - Light | C140: ='DMC Threads - By Number'!O11 -> 0 | D140: 12
A141: 524 | B141: Fern Green - Very Light | C141: ='DMC Threads - By Number'!O12 -> 0 | D141: 12
A142: 535 | B142: Ash Gray - Very Light | C142: ='DMC Threads - By Number'!O13 -> 0 | D142: 20
...

Sheet DMC Threads - By Color (2)
B2: SEARCH | C2: Name | D2: Owned | E2: Column
B3: 310 | C3: =VLOOKUP(B3,Sheet2!A1:C575,2,FALSE) -> Black | D3: =VLOOKUP(B3,Sheet2!A1:C575,3,FALSE) -> 0 | E3: =VLOOKUP(B3,Sheet2!A1:D575,4,FALSE) -> 20
G4: By Lord Libidan
B5: Column 1 | G5: Column 2 | L5: Column 3 | Q5: Column 4 | V5: Column 5 | AA5: Column 6 | AF5: Column 7 | AK5: Column 8 | AP5: Column 9 | AU5: Column 10 | AZ5: Column 11 | BE5: Column 12 | BJ5: Column 13 | BO5: Column 14 | BT5: Column 15 | BY5: Column 16 | CD5: Column 17 | CI5: Column 18 | CN5: Column 19 | CS5: Column 20 | CX5: Column 21 | DC5: Column 22 | DH5: Column 23 | DM5: Column 24 | DR5: Column 25 | DW5: Column 26
B6: Number | C6: Name | D6: Color | E6: Owned | G6: Number | H6: Name | I6: Color | J6: Owned | L6: Number | M6: Name | N6: Color | O6: Owned | Q6: Number | R6: Name | S6: Color | T6: Owned | V6: Number | W6: Name | X6: Color | Y6: Owned | AA6: Number | AB6: Name | AC6: Color | AD6: Owned | AF6: Number | AG6: Name | AH6: Color | AI6: Owned | AK6: Number | AL6: Name | AM6: Color | AN6: Owned | AP6: Number | AQ6: Name | AR6: Color | AS6: Owned | AU6: Number | AV6: Name | AW6: Color | AX6: Owned | AZ6: Number | BA6: Name | BB6: Color | BC6: Owned | BE6: Number | BF6: Name | BG6: Color | BH6: Owned | BJ6: Number | BK6: Name | BL6: Color | BM6: Owned | BO6: Number | BP6: Name | BQ6: Color | BR6: Owned | BT6: Number | BU6: Name | BV6: Color | BW6: Owned | BY6: Number | BZ6: Name | CA6: Color | CB6: Owned | CD6: Number | CE6: Name | CF6: Color | CG6: Owned | CI6: Number | CJ6: Name | CK6: Color | CL6: Owned | CN6: Number | CO6: Name | CP6: Color | CQ6: Owned | CS6: Number | CT6: Name | CU6: Color | CV6: Owned | CX6: Number | CY6: Name | CZ6: Color | DA6: Owned | DC6: Number | DD6: Name | DE6: Color | DF6: Owned | DH6: Number | DI6: Name | DJ6: Color | DK6: Owned | DM6: Number | DN6: Name | DO6: Color | DP6: Owned | DR6: Number | DS6: Name | DT6: Color | DU6: Owned | DW6: Number | DX6: Name | DY6: Color | DZ6: Owned
B7: 3713 | C7: Salmon - Very Light | G7: 894 | H7: Carnation - Very Light | L7: 23 | M7: Apple Blossom | Q7: 778 | R7: Antique Mauve - Very Light | V7: 3743 | W7: Antique Violet - Very Light | AA7: 3840 | AB7: Lavender Blue - Light | AF7: 159 | AG7: Petrol Blue - Light | AK7: 828 | AL7: Blue - Ultra Very Light | AP7: 964 | AQ7: Seagreen - Light | AU7: 955 | AV7: Nile Green - Light | AZ7: 14 | BA7: Apple Green - Pale | BE7: 10 | BF7: Tender Green - Very Light | BJ7: 17 | BK7: Yellow Plum - Light | BO7: 676 | BP7: Old Gold - Light | BT7: 445 | BU7: Lemon - Light | BY7: 951 | BZ7: Tawny - Light | CD7: 948 | CE7: Peach - Very Light | CI7: 453 | CJ7: Shell Gray - Light | CN7: 3865 | CO7: Winter White | CS7: 3072 | CT7: Beaver Gray - Very Light | CX7: 48 | CY7: Variegated - Baby Pink | DC7: E316 | DD7: Metallic - Pink Amethyst | DH7: E5200 | DI7: Metallic - White | DM7: 4010 | DN7: Variations - Winter Sky | DR7: 4130 | DS7: Variations - Chilean Sunset | DW7: 5282 | DX7: Metallic Pearl - Gold
B8: 761 | C8: Salmon - Light | G8: 893 | H8: Carnation - Light | L8: 3689 | M8: Mauve - Light | Q8: 3727 | R8: Antique Mauve - Light | V8: 3042 | W8: Antique Violet - Light | AA8: 3839 | AB8: Lavender Blue - Medium | AF8: 160 | AG8: Petrol Blue - Medium | AK8: 3761 | AL8: Sky Blue - Light | AP8: 959 | AQ8: Seagreen - Medium | AU8: 13 | AV8: Nile Green - Medium Light | AZ8: 15 | BA8: Apple Green | BE8: 11 | BF8: Tender Green - Light | BJ8: 18 | BK8: Yellow Plum | BO8: 729 | BP8: Old Gold - Medium | BT8: 307 | BU8: Lemon | BY8: 3856 | BZ8: Mahogany - Ultra Very Light | CD8: 754 | CE8: Peach - Light | CI8: 452 | CJ8: Shell Gray - Medium | CN8: Ecru | CO8: Ecru/off-white | CS8: 647 | CT8: Beaver Gray - Medium | CX8: 107 | CY8: Variegated - Carnation | DC8: E718 | DD8: Metallic - Pink Garnet | DH8: E746 | DI8: Metallic - Cream | DM8: 4015 | DN8: Variations - Stormy Skies | DR8: 4140 | DS8: Variations - Driftwood | DW8: 5283 | DX8: Metallic Pearl - Silver
B9: 760 | C9: Salmon | G9: 892 | H9: Carnation - Medium | L9: 3688 | M9: Mauve - Medium | Q9: 316 | R9: Antique Mauve - Medium | V9: 3041 | W9: Antique Violet - Medium | AA9: 3838 | AB9: Lavender Blue - Dark | AF9: 161 | AG9: Petrol Blue - Dark | AK9: 519 | AL9: Sky Blue | AP9: 958 | AQ9: Seagreen - Dark | AU9: 954 | AV9: Nile Green | AZ9: 16 | BA9: Chartreuse - Light | BE9: 12 | BF9: Tender Green | BJ9: 834 | BK9: Golden Olive - Very Light | BO9: 680 | BP9: Old Gold - Dark | BT9: 973 | BU9: Canary - Bright | BY9: 722 | BZ9: Orange Spice - Light | CD9: 3771 | CE9: Peach - Dark | CI9: 451 | CJ9: Shell Gray - Dark | CN9: 822 | CO9: Beige Gray - Light | CS9: 3023 | CT9: Brown Gray - Light | CX9: 115 | CY9: Variegated - Garnet | DC9: E3837 | DD9: Metallic - Purple Ruby | DH9: E967 | DI9: Metallic - Soft Peach | DM9: 4020 | DN9: Variations - Tropical Waters | DR9: 4145 | DS9: Variations - Sandune
B10: 3712 | C10: Salmon - Medium | G10: 891 | H10: Carnation - Dark | L10: 3687 | M10: Mauve | Q10: 3726 | R10: Antique Mauve - Dark | V10: 3740 | W10: Antique Violet - Dark | AA10: 800 | AB10: Delft Blue - Pale | AF10: 3756 | AG10: Baby Blue - Light | AK10: 518 | AL10: Wedgewood - Light | AP10: 3812 | AQ10: Seagreen - Very Dark | AU10: 913 | AV10: Nile Green - Medium | AZ10: 704 | BA10: Chartreuse - Bright | BE10: 165 | BF10: Green - Bright | BJ10: 833 | BK10: Golden Olive - Light | BO10: 3829 | BP10: Old Gold - Very Dark | BT10: 444 | BU10: Lemon - Dark | BY10: 721 | BZ10: Orange Spice - Medium | CD10: 758 | CE10: Terra Cotta - Very Light | CI10: 3861 | CJ10: Cocoa - Light | CN10: 644 | CO10: Beige Gray - Medium | CS10: 3022 | CT10: Brown Gray - Medium | CX10: 99 | CY10: Variegated - Mauve | DC10: E155 | DD10: Metallic - Amethyst | DH10: E818 | DI10: Metallic - Soft Pink | DM10: 4025 | DN10: Variations - Caribbean Bay | DR10: 4150 | DS10: Variations - Desert Sand
B11: 3328 | C11: Salmon - Dark | G11: 818 | H11: Baby Pink | L11: 3803 | M11: Mauve - Dark | Q11: 315 | R11: Antique Mauve - Medium Dark | V11: 27 | W11: White Violet | AA11: 809 | AB11: Delft Blue | AF11: 775 | AG11: Baby Blue - Very Light | AK11: 3760 | AL11: Wedgewood - Medium | AP11: 3851 | AQ11: Bright Green - Light | AU11: 912 | AV11: Emerald Green - Light | AZ11: 703 | BA11: Chartreuse | BE11: 3819 | BF11: Moss Green - Light | BJ11: 832 | BK11: Golden Olive | BO11: 3822 | BP11: Straw - Light | BT11: 3078 | BU11: Golden Yellow - Very Light | BY11: 720 | BZ11: Orange Spice - Dark | CD11: 3778 | CE11: Terra Cotta - Light | CI11: 3860 | CJ11: Cocoa | CN11: 642 | CO11: Beige Gray - Dark | CS11: 3024 | CT11: Brown Gray - Very Light | CX11: 52 | CY11: Variegated - Violet | DC11: E825 | DD11: Metallic - Blue Sapphire | DH11: E211 | DI11: Metallic - Lilac | DM11: 4030 | DN11: Variations - Monet's Garden | DR11: 4160 | DS11: Variations - Glistening Pearl
B12: 347 | C12: Salmon - Very Dark | G12: 957 | H12: Geranium - Pale | L12: 3685 | M12: Mauve - Very Dark | Q12: 3802 | R12: Antique Mauve - Very Dark | V12: 28 | W12: Eggplant - Medium Light | AA12: 799 | AB12: Delft Blue - Medium | AF12: 3841 | AG12: Baby Blue - Pale | AK12: 517 | AL12: Wedgewood - Dark | AP12: 943 | AQ12: Aquamarine - Medium | AU12: 911 | AV12: Emerald Green - Medium | AZ12: 702 | BA12: Kelly Green | BE12: 166 | BF12: Lime Green | BJ12: 831 | BK12: Golden Olive - Medium | BO12: 3821 | BP12: Straw | BT12: 727 | BU12: Topaz - Very Light | BY12: 3825 | BZ12: Pumpkin - Pale | CD12: 356 | CE12: Terra Cotta - Medium | CI12: 779 | CJ12: Brown | CN12: 640 | CO12: Beige Gray - Very Dark | CS12: 648 | CT12: Beaver Gray - Light | CX12: 93 | CY12: Variegated - Blue Haze | DC12: E3843 | DD12: Metallic - Light Blue Sapphire | DH12: E3747 | DI12: Metallic - Sky Blue | DM12: 4040 | DN12: Variations - Water Lillies | DR12: 4170 | DS12: Variations - Whispering Wind
B13: 353 | C13: Peach | G13: 956 | H13: Geranium | L13: 605 | M13: Cranberry - Very Light | Q13: 902 | R13: Garnet - Very Dark | V13: 29 | W13: Eggplant | AA13: 798 | AB13: Delft Blue - Dark | AF13: 3325 | AG13: Baby Blue - Light | AK13: 3842 | AL13: Wedgewood - Dark | AP13: 3850 | AQ13: Bright Green - Dark | AU13: 910 | AV13: Emerald Green - Dark | AZ13: 701 | BA13: Green - Light | BE13: 581 | BF13: Moss Green | BJ13: 830 | BK13: Golden Olive - Dark | BO13: 3820 | BP13: Straw - Dark | BT13: 726 | BU13: Topaz - Light | BY13: 922 | BZ13: Copper - Light | CD13: 3830 | CE13: Terra Cotta | CI13: 9 | CJ13: Cocoa - Very Dark | CN13: 3787 | CO13: Brown Gray - Dark | CS13: 646 | CT13: Beaver Gray - Dark | CX13: 121 | CY13: Variegated - Delft Blue | DC13: E334 | DD13: Metallic - Blue Topaz | DH13: E747 | DI13: Metallic - Baby Blue | DM13: 4045 | DN13: Variations - Evergreen Forest | DR13: 4180 | DS13: Variations - Rose Petals
B14: 352 | C14: Coral - Light | G14: 3708 | H14: Melon - Light | L14: 604 | M14: Cranberry - Light | Q14: 3836 | R14: Grape - Light | V14: 3747 | W14: Blue Violet - Very Light | AA14: 797 | AB14: Royal Blue | AF14: 3755 | AG14: Baby Blue | AK14: 311 | AL14: Blue - Medium | AP14: 993 | AQ14: Aquamarine - Very Light | AU14: 909 | AV14: Emerald Green - Very Dark | AZ14: 700 | BA14: Green - Bright | BE14: 580 | BF14: Moss Green - Dark | BJ14: 829 | BK14: Golden Olive - Very Dark | BO14: 3852 | BP14: Straw - Very Dark | BT14: 725 | BU14: Topaz | BY14: 921 | BZ14: Copper | CD14: 355 | CE14: Terra Cotta - Dark | CI14: 712 | CJ14: Cream | CN14: 3021 | CO14: Brown Gray - Very Dark | CS14: 645 | CT14: Beaver Gray - Very Dark | CX14: 67 | CY14: Variegated - Baby Blue | DC14: E3849 | DD14: Metallic - Aquamarine Blue | DH14: E966 | DI14: Metallic - Lime | DM14: 4050 | DN14: Variations - Roaming Pastures | DR14: 4190 | DS14: Variations - Ocean Coral
B15: 351 | C15: Coral | G15: 3706 | H15: Melon - Medium | L15: 603 | M15: Cranberry - Light Medium | Q15: 3835 | R15: Grape - Medium | V15: 341 | W15: Blue Violet - Light | AA15: 796 | AB15: Royal Blue - Dark | AF15: 334 | AG15: Baby Blue - Medium | AK15: 747 | AL15: Sky Blue - Very Light | AP15: 992 | AQ15: Aquamarine - Light | AU15: 3818 | AV15: Emerald Green - Ultra Very Dark | AZ15: 699 | BA15: Green | BE15: 523 | BF15: Fern Green - Light | BJ15: 746 | BK15: Off White | BO15: 728 | BP15: Golden Yellow | BT15: 972 | BU15: Canary - Deep | BY15: 920 | BZ15: Copper - Medium | CD15: 3777 | CE15: Terra Cotta - Very Dark | CI15: 739 | CJ15: Tan - Ultra Very Light | CN15: 844 | CO15: Beaver Gray - Ultra Dark | CS15: B5200 | CT15: Snow White | CX15: 125 | CY15: Variegated - Seafoam Green | DC15: E703 | DD15: Metallic - Light Green Emerald | DH15: E168 | DI15: Metallic - Silver | DM15: 4060 | DN15: Variations - Weeping Willow | DR15: 4200 | DS15: Variations - Wild Fire
B16: 350 | C16: Coral - Medium | G16: 3705 | H16: Melon - Dark | L16: 602 | M16: Cranberry - Medium | Q16: 3834 | R16: Grape - Dark | V16: 156 | W16: Blue - Medium | AA16: 820 | AB16: Royal Blue - Very Dark | AF16: 322 | AG16: Baby Blue | AK16: 3766 | AL16: Peacock Blue - Light | AP16: 3814 | AQ16: Aquamarine | AU16: 369 | AV16: Pistachio Green - Very Light | AZ16: 907 | BA16: Parrot Green - Light | BE16: 3053 | BF16: Green Gray | BJ16: 677 | BK16: Old Gold - Very Light | BO16: 783 | BP16: Topaz - Medium | BT16: 745 | BU16: Yellow - Light Pale | BY16: 919 | BZ16: Red Copper | CD16: 3779 | CE16: Terra Cotta - Ultra Very Light | CI16: 738 | CJ16: Tan - Very Light | CN16: 3033 | CO16: Mocha Brown - Very Light | CS16: Blanc^ | CT16: White | CX16: 92 | CY16: Variegated - Avocado | DC16: E699 | DD16: Metallic - Green Emerald | DH16: E415 | DI16: Metallic - Pewter | DM16: 4065 | DN16: Variations - Morning Meadow | DR16: 4210 | DS16: Variations - Radiant Ruby
B17: 349 | C17: Coral - Dark | G17: 963 | H17: Dusty Rose - Ultra Very Light | L17: 601 | M17: Cranberry - Dark | Q17: 154 | R17: Red - Very Dark | V17: 340 | W17: Blue Violet - Medium | AA17: 162 | AB17: Baby Blue - Light | AF17: 312 | AG17: Baby Blue - Very Dark | AK17: 807 | AL17: Peacock Blue | AP17: 991 | AQ17: Aquamarine - Dark | AU17: 368 | AV17: Pistachio Green - Light | AZ17: 906 | BA17: Parrot Green - Medium | BE17: 3052 | BF17: Green Gray - Medium | BJ17: 422 | BK17: Hazelnut Brown - Light | BO17: 782 | BP17: Topaz - Dark | BT17: 744 | BU17: Yellow - Pale | BY17: 918 | BZ17: Red Copper - Dark | CD17: 3859 | CE17: Rosewood - Light | CI17: 437 | CJ17: Tan - Light | CN17: 3782 | CO17: Mocha Brown - Light | CS17: White^ | CT17: White | CX17: 94 | CY17: Variegated - Khaki Green | DC17: E135 | DD17: Metallic - Golden Dawn | DH17: E317 | DI17: Metallic - Titanium | DM17: 4070 | DN17: Variations - Autumn Leaves | DR17: 4215 | DS17: Variations - Northern Lights
B18: 817 | C18: Coral Red - Very Dark | G18: 3716 | H18: Dusty Rose - Very Light | L18: 600 | M18: Cranberry - Very Dark | Q18: 24 | R18: White Lavender | V18: 155 | W18: Forget-me-not Blue | AA18: 827 | AB18: Blue - Very Light | AF18: 803 | AG18: Blue - Deep | AK18: 3765 | AL18: Peacock Blue - Very Dark | AP18: 966 | AQ18: Baby Green - Medium | AU18: 320 | AV18: Pistachio Green - Medium | AZ18: 905 | BA18: Parrot Green - Dark | BE18: 3051 | BF18: Green Gray - Dark | BJ18: 3828 | BK18: Hazelnut Brown | BO18: 780 | BP18: Topaz - Ultra Very Dark | BT18: 743 | BU18: Yellow - Medium | BY18: 3770 | BZ18: Tawny - Very Light | CD18: 3858 | CE18: Rosewood - Medium | CI18: 436 | CJ18: Tan | CN18: 3032 | CO18: Mocha Brown - Medium | CS18: 762 | CT18: Pearl Gray - Very Light | CX18: 90 | CY18: Variegated - Yellow | DC18: E130 | DD18: Metallic - Gemstones | DH18: E677 | DI18: Metallic - White Gold | DM18: 4075 | DN18: Variations - Wheat Fields | DR18: 4220 | DS18: Variations - Lavender Fields
B19: 304 | C19: Red - Medium | G19: 962 | H19: Dusty Rose - Medium | L19: 3806 | M19: Cyclamen Pink - Light | Q19: 25 | R19: Lavender - Ultra Light | V19: 3746 | W19: Blue Violet - Dark | AA19: 813 | AB19: Blue - Light | AF19: 336 | AG19: Blue | AK19: 3811 | AL19: Turquoise - Very Light | AP19: 564 | AQ19: Jade - Very Light | AU19: 367 | AV19: Pistachio Green - Dark | AZ19: 904 | BA19: Parrot Green - Very Dark | BE19: 524 | BF19: Fern Green - Very Light | BJ19: 420 | BK19: Hazelnut Brown - Dark | BO19: 3823 | BP19: Yellow - Ultra Pale | BT19: 742 | BU19: Tangerine - Light | BY19: 945 | BZ19: Tawny | CD19: 3857 | CE19: Rosewood - Dark | CI19: 435 | CJ19: Brown - Very Light | CN19: 3790 | CO19: Beige Gray - Ultra Dark | CS19: 415 | CT19: Pearl Gray | CX19: 51 | CY19: Variegated - Burnt Orange | DC19: E3685 | DD19: Metallic - Rosewood | DH19: E3821 | DI19: Metallic - Light Gold | DM19: 4077 | DN19: Variations - Morning Sunshine | DR19: 4230 | DS19: Variations - Crystal Water
B20: 3833 | C20: Raspberry - Light | G20: 961 | H20: Dusty Rose - Dark | L20: 3805 | M20: Cyclamen Pink | Q20: 26 | R20: Lavender - Pale | V20: 333 | W20: Blue Violet - Very Dark | AA20: 826 | AB20: Blue - Medium | AF20: 823 | AG20: Blue - Dark | AK20: 598 | AL20: Turquoise - Light | AP20: 563 | AQ20: Jade - Light | AU20: 319 | AV20: Pistachio Green - Very Dark | AZ20: 472 | BA20: Avocado Green - Ultra Light | BE20: 522 | BF20: Fern Green | BJ20: 869 | BK20: Hazelnut Brown - Very Dark | BO20: 3855 | BP20: Autumn Gold - Light | BT20: 741 | BU20: Tangerine - Medium | BY20: 402 | BZ20: Mahogany - Very Light | CD20: 20 | CE20: Shrimp | CI20: 434 | CJ20: Brown - Light | CN20: 3781 | CO20: Mocha Brown - Dark | CS20: 318 | CT20: Steel Gray - Light | CX20: 106 | CY20: Variegated - Coral | DC20: E815 | DD20: Metallic - Dark Red Ruby | DH20: E3852 | DI20: Metallic - Dark Gold | DM20: 4080 | DN20: Variations - Daffodil Fields | DR20: 4235 | DS20: Variations - Arctic Sea
B21: 3832 | C21: Raspberry - Medium | G21: 309 | H21: Rose - Dark | L21: 3804 | M21: Cyclamen Pink - Dark | Q21: 211 | R21: Lavender - Light | V21: 30 | W21: Blueberry - Medium Light | AA21: 825 | AB21: Blue - Dark | AF21: 939 | AG21: Blue - Very Dark | AK21: 597 | AL21: Turquoise | AP21: 562 | AQ21: Jade - Medium | AU21: 890 | AV21: Pistachio Green - Ultra Dark | AZ21: 471 | BA21: Avocado Green - Very Light | BE21: 520 | BF21: Fern Green - Dark | BJ21: 613 | BK21: Drab Brown - Very Light | BO21: 19 | BP21: Autumn Gold - Medium Light | BT21: 740 | BU21: Tangerine | BY21: 3776 | BZ21: Mahogany - Light | CD21: 21 | CE21: Alizarian - Light | CI21: 433 | CJ21: Brown - Medium | CN21: 5 | CO21: Driftwood - Light | CS21: 414 | CT21: Steel Gray - Dark | CX21: 111 | CY21: Variegated - Mustard | DC21: E321 | DD21: Metallic - Red Ruby | DM21: 4090 | DN21: Variations - Golden Oasis | DR21: 4240 | DS21: Variations - Mid Summer Night
B22: 3831 | C22: Raspberry - Dark | G22: 819 | H22: Baby Pink - Light | L22: 3609 | M22: Plum - Ultra Light | Q22: 210 | R22: Lavender - Medium | V22: 31 | W22: Blueberry | AA22: 824 | AB22: Blue - Very Dark | AF22: 3753 | AG22: Antique Blue - Ultra Very Light | AK22: 3810 | AL22: Turquoise - Dark | AP22: 505 | AQ22: Grass Green - Dark | AU22: 164 | AV22: Green - Light | AZ22: 470 | BA22: Avocado Green - Light | BE22: 734 | BF22: Olive Green - Light | BJ22: 612 | BK22: Drab Brown - Light | BO22: 3854 | BP22: Autumn Gold - Medium | BT22: 970 | BU22: Pumpkin - Light | BY22: 301 | BZ22: Mahogany - Medium | CD22: 22 | CE22: Alizarian | CI22: 801 | CJ22: Coffee Brown - Dark | CN22: 6 | CO22: Driftwood - Medium Light | CS22: 1 | CT22: White Tin | CX22: 105 | CY22: Variegated - Tan/Brown | DC22: E301 | DD22: Metallic - Copper | DM22: 4100 | DN22: Variations - Summer Breeze
B23: 777 | C23: Red - Deep | G23: 3326 | H23: Rose - Light | L23: 3608 | M23: Plum - Very Light | Q23: 209 | R23: Lavender - Dark | V23: 32 | W23: Blueberry - Dark | AA23: 996 | AB23: Electric Blue - Medium | AF23: 3752 | AG23: Antique Blue - Very Light | AK23: 3809 | AL23: Turquoise - Very Dark | AP23: 3817 | AQ23: Celadon Green - Light | AU23: 989 | AV23: Forest Green | AZ23: 469 | BA23: Avocado Green | BE23: 733 | BF23: Olive Green - Medium | BJ23: 611 | BK23: Drab Brown | BO23: 3853 | BP23: Autumn Gold - Dark | BT23: 947 | BU23: Burnt Orange | BY23: 400 | BZ23: Mahogany - Dark | CD23: 3774 | CE23: Desert Sand - Very Light | CI23: 898 | CJ23: Coffee Brown - Very Dark | CN23: 7 | CO23: Driftwood | CS23: 2 | CT23: Tin | CX23: 69 | CY23: Variegated - Terra Cotta | DC23: E436 | DD23: Metallic - Golden Oak | DM23: 4110 | DN23: Variations - Sunrise
B24: 3801 | C24: Melon - Very Dark | G24: 899 | H24: Rose - Medium | L24: 3607 | M24: Plum - Light | Q24: 208 | R24: Lavender - Very Dark | V24: 157 | W24: Blue - Light | AA24: 3843 | AB24: Electric Blue | AF24: 932 | AG24: Antique Blue - Light | AK24: 3808 | AL24: Turquoise - Ultra Very Dark | AP24: 3816 | AQ24: Celadon Green | AU24: 988 | AV24: Forest Green - Medium | AZ24: 937 | BA24: Avocado Green - Medium | BE24: 732 | BF24: Olive Green | BJ24: 610 | BK24: Drab Brown - Dark | BO24: 3827 | BP24: Golden Brown - Pale | BT24: 946 | BU24: Burnt Orange - Medium | BY24: 300 | BZ24: Mahogany - Very Dark | CD24: 950 | CE24: Desert Sand - Light | CI24: 938 | CJ24: Coffee Brown - Ultra Dark | CN24: 8 | CO24: Driftwood - Dark | CS24: 3 | CT24: Tin - Medium | CX24: 53 | CY24: Variegated - Steel Grey | DC24: E898 | DD24: Metallic - Dark Oak | DM24: 4120 | DN24: Variations - Tropical Sunset
B25: 666 | C25: Red - Bright | G25: 335 | H25: Rose | L25: 718 | M25: Plum | Q25: 3837 | R25: Lavender - Ultra Dark | V25: 794 | W25: Cornflower Blue - Light | AA25: 995 | AB25: Electric Blue - Dark | AF25: 931 | AG25: Antique Blue - Medium | AK25: 928 | AL25: Gray Green - Very Light | AP25: 163 | AQ25: Green | AU25: 987 | AV25: Forest Green - Dark | AZ25: 936 | BA25: Avocado Green - Very Dark | BE25: 730 | BF25: Olive Green - Very Dark | BJ25: 3047 | BK25: Yellow Beige - Light | BO25: 977 | BP25: Golden Brown - Light | BT25: 900 | BU25: Burnt Orange - Dark | BY25: 225 | BZ25: Shell Pink - Ultra Very Light | CD25: 3064 | CE25: Desert Sand | CI25: 3371 | CJ25: Black Brown | CN25: 3866 | CO25: Mocha Brown - Ultra Very Light | CS25: 4 | CT25: Tin - Dark | DC25: E310 | DD25: Metallic - Ebony | DM25: 4124 | DN25: Variations - Bonfire
B26: 321 | C26: Red | G26: 326 | H26: Rose - Very Dark | L26: 917 | M26: Plum - Medium | Q26: 327 | R26: Violet | V26: 793 | W26: Cornflower Blue - Medium | AA26: 3846 | AB26: Bright Turquoise - Light | AF26: 930 | AG26: Antique Blue - Dark | AK26: 927 | AL26: Gray Green - Light | AP26: 3815 | AQ26: Celadon Green - Dark | AU26: 986 | AV26: Forest Green - Very Dark | AZ26: 935 | BA26: Avocado Green - Dark | BE26: 3013 | BF26: Khaki Green - Light | BJ26: 3046 | BK26: Yellow Beige - Medium | BO26: 976 | BP26: Golden Brown - Medium | BT26: 967 | BU26: Peach - Light | BY26: 224 | BZ26: Shell Pink - Very Light | CD26: 407 | CE26: Desert Sand - Dark | CI26: 543 | CJ26: Beige Brown - Ultra Very Light | CN26: 842 | CO26: Beige Brown - Very Light | CS26: 535 | CT26: Ash Gray - Very Light | DC26: E980 | DD26: Neon - Neon Yellow | DM26: 4126 | DN26: Variations - Desert Canyon
B27: 498 | C27: Red - Dark | G27: 151 | H27: Pink | L27: 915 | M27: Plum - Dark | Q27: 153 | R27: Lilac | V27: 3807 | W27: Cornflower Blue | AA27: 3845 | AB27: Bright Turquoise - Medium | AF27: 3750 | AG27: Antique Blue - Very Dark | AK27: 926 | AL27: Gray Green - Medium | AP27: 561 | AQ27: Jade - Very Dark | AU27: 772 | AV27: Yellow Green - Very Light | AZ27: 934 | BA27: Avocado Green - BLACK | BE27: 3012 | BF27: Khaki Green - Medium | BJ27: 3045 | BK27: Yellow Beige - Dark | BO27: 3826 | BP27: Golden Brown | BT27: 3824 | BU27: Apricot - Light | BY27: 152 | BZ27: Tawny - Dark | CD27: 3772 | CE27: Desert Sand - Very Dark | CI27: 3864 | CJ27: Mocha Beige - Light | CN27: 841 | CO27: Beige Brown - Light | CS27: 168 | CT27: Silver Gray | DC27: E990 | DD27: Neon - Neon Green | DM27: 4128 | DN27: Variations - Gold Coast
B28: 816 | C28: Garnet | G28: 3354 | H28: Dusty Rose - Light | L28: 33 | M28: Fuchsia | Q28: 554 | R28: Violet - Light | V28: 792 | W28: Cornflower Blue - Dark | AA28: 3844 | AB28: Bright Turquoise - Dark | AH28: By Lord Libidan | AK28: 3768 | AL28: Gray Green - Dark | AP28: 3813 | AQ28: Blue Green - Light | AU28: 3348 | AV28: Yellow Green - Light | AZ28: 3364 | BA28: Pine Green | BE28: 3011 | BF28: Khaki Green - Dark | BJ28: 167 | BK28: Khaki Brown | BO28: 975 | BP28: Golden Brown - Dark | BT28: 3341 | BU28: Apricot | BY28: 223 | BZ28: Shell Pink - Light | CD28: 632 | CE28: Desert Sand - Ultra Very Dark | CI28: 3863 | CJ28: Mocha Beige - Medium | CN28: 840 | CO28: Beige Brown - Medium | CS28: 169 | CT28: Pewter Gray | DC28: E940 | DD28: Glow-In-The-Dark
B29: 815 | C29: Garnet - Medium | G29: 3733 | H29: Dusty Rose | L29: 34 | M29: Fuchsia - Dark | Q29: 553 | R29: Violet | V29: 158 | W29: Blue - Dark | AK29: 924 | AL29: Gray Green - Very Dark | AP29: 503 | AQ29: Blue Green - Medium | AU29: 3347 | AV29: Yellow Green - Medium | AZ29: 3363 | BA29: Pine Green - Medium | BE29: 372 | BF29: Mustard - Light | BT29: 3340 | BU29: Apricot - Medium | BY29: 3722 | BZ29: Shell Pink - Medium | CI29: 3862 | CJ29: Mocha Beige - Dark | CN29: 839 | CO29: Beige Brown - Dark | CS29: 317 | CT29: Pewter Gray
B30: 814 | C30: Garnet - Dark | G30: 3731 | H30: Dusty Rose - Very Dark | L30: 35 | M30: Fuchsia - Very Dark | Q30: 552 | R30: Violet - Medium | V30: 791 | W30: Cornflower Blue - Very Dark | AK30: 3849 | AL30: Teal Green - Light | AP30: 502 | AQ30: Blue Green | AU30: 3346 | AV30: Hunter Green | AZ30: 3362 | BA30: Pine Green - Dark | BE30: 371 | BF30: Mustard | BT30: 608 | BU30: Orange - Bright | BY30: 3721 | BZ30: Shell Pink - Dark | CI30: 3031 | CJ30: Mocha Brown - Very Dark | CN30: 838 | CO30: Beige Brown - Very Dark | CS30: 413 | CT30: Pewter Gray - Dark
G31: 3350 | H31: Dusty Rose - Ultra Dark | Q31: 550 | R31: Violet - Very Dark | AK31: 3848 | AL31: Teal Green - Medium | AP31: 501 | AQ31: Blue Green - Dark | AU31: 3345 | AV31: Hunter Green - Dark | BE31: 370 | BF31: Mustard - Medium | BT31: 606 | BU31: Orange-red - Bright | BY31: 221 | BZ31: Shell Pink - Very Dark | CS31: 3799 | CT31: Pewter Gray - Very Dark
G32: 150 | H32: Red - Bright | L32: Updated March 2025 | AK32: 3847 | AL32: Teal Green - Dark | AP32: 500 | AQ32: Blue Green - Very Dark | AU32: 895 | AV32: Hunter Green - Very Dark | CS32: 310 | CT32: Black
CS33: ^ Depending on your country you may find either/both.
B34: This list does not include:
B35: Discontinued Threads
B36: Threads Not On The International Color Card
B37: Coloris Threads
B38: Étoile Threads
B39: Satin Threads
B40: Fluorescent Threads

Sheet Sheet2
A1: 3713 | B1: Salmon - Very Light | C1: ='DMC Threads - By Color'!E7 -> 0 | D1: 1
A2: 761 | B2: Salmon - Light | C2: ='DMC Threads - By Color'!E8 -> 0 | D2: 1
A3: 760 | B3: Salmon | C3: ='DMC Threads - By Color'!E9 -> 0 | D3: 1
A4: 3712 | B4: Salmon - Medium | C4: ='DMC Threads - By Color'!E10 -> 0 | D4: 1
A5: 3328 | B5: Salmon - Dark | C5: ='DMC Threads - By Color'!E11 -> 0 | D5: 1
A6: 347 | B6: Salmon - Very Dark | C6: ='DMC Threads - By Color'!E12 -> 0 | D6: 1
A7: 353 | B7: Peach | C7: ='DMC Threads - By Color'!E13 -> 0 | D7: 1
A8: 352 | B8: Coral - Light | C8: ='DMC Threads - By Color'!E14 -> 0 | D8: 1
A9: 351 | B9: Coral | C9: ='DMC Threads - By Color'!E15 -> 0 | D9: 1
A10: 350 | B10: Coral - Medium | C10: ='DMC Threads - By Color'!E16 -> 0 | D10: 1
A11: 349 | B11: Coral - Dark | C11: ='DMC Threads - By Color'!E17 -> 0 | D11: 1
A12: 817 | B12: Coral Red - Very Dark | C12: ='DMC Threads - By Color'!E18 -> 0 | D12: 1
... A24: 814 | B24: Garnet - Dark | C24: ='DMC Threads - By Color'!E30 -> 0 | D24: 1
A25: 894 | B25: Carnation - Very Light | C25: ='DMC Threads - By Color'!J7 -> 0 | D25: 2
A26: 893 | B26: Carnation - Light | C26: ='DMC Threads - By Color'!J8 -> 0 | D26: 2
A27: 892 | B27: Carnation - Medium | C27: ='DMC Threads - By Color'!J9 -> 0 | D27: 2
A28: 891 | B28: Carnation - Dark | C28: ='DMC Threads - By Color'!J10 -> 0 | D28: 2
A29: 818 | B29: Baby Pink | C29: ='DMC Threads - By Color'!J11 -> 0 | D29: 2
A30: 957 | B30: Geranium - Pale | C30: ='DMC Threads - By Color'!J12 -> 0 | D30: 2
A31: 956 | B31: Geranium | C31: ='DMC Threads - By Color'!J13 -> 0 | D31: 2
A32: 3708 | B32: Melon - Light | C32: ='DMC Threads - By Color'!J14 -> 0 | D32: 2
A33: 3706 | B33: Melon - Medium | C33: ='DMC Threads - By Color'!J15 -> 0 | D33: 2
A34: 3705 | B34: Melon - Dark | C34: ='DMC Threads - By Color'!J16 -> 0 | D34: 2
A35: 963 | B35: Dusty Rose - Ultra Very Light | C35: ='DMC Threads - By Color'!J17 -> 0 | D35: 2
A36: 3716 | B36: Dusty Rose - Very Light | C36: ='DMC Threads - By Color'!J18 -> 0 | D36: 2
... A50: 150 | B50: Red - Bright | C50: ='DMC Threads - By Color'!J32 -> 0 | D50: 2
A51: 23 | B51: Apple Blossom | C51: ='DMC Threads - By Color'!O7 -> 0 | D51: 3
A52: 3689 | B52: Mauve - Light | C52: ='DMC Threads - By Color'!O8 -> 0 | D52: 3
A53: 3688 | B53: Mauve - Medium | C53: ='DMC Threads - By Color'!O9 -> 0 | D53: 3
A54: 3687 | B54: Mauve | C54: ='DMC Threads - By Color'!O10 -> 0 | D54: 3
A55: 3803 | B55: Mauve - Dark | C55: ='DMC Threads - By Color'!O11 -> 0 | D55: 3
A56: 3685 | B56: Mauve - Very Dark | C56: ='DMC Threads - By Color'!O12 -> 0 | D56: 3
A57: 605 | B57: Cranberry - Very Light | C57: ='DMC Threads - By Color'!O13 -> 0 | D57: 3
A58: 604 | B58: Cranberry - Light | C58: ='DMC Threads - By Color'!O14 -> 0 | D58: 3
A59: 603 | B59: Cranberry - Light Medium | C59: ='DMC Threads - By Color'!O15 -> 0 | D59: 3
A60: 602 | B60: Cranberry - Medium | C60: ='DMC Threads - By Color'!O16 -> 0 | D60: 3
A61: 601 | B61: Cranberry - Dark | C61: ='DMC Threads - By Color'!O17 -> 0 | D61: 3
A62: 600 | B62: Cranberry - Very Dark | C62: ='DMC Threads - By Color'!O18 -> 0 | D62: 3
... A74: 35 | B74: Fuchsia - Very Dark | C74: ='DMC Threads - By Color'!O30 -> 0 | D74: 3
A75: 778 | B75: Antique Mauve - Very Light | C75: ='DMC Threads - By Color'!T7 -> 0 | D75: 4
...

Sheet Print - By Number
A1: Number | B1: Name | C1: Color | D1: Owned | E1: Notes
A2: Ecru | B2: Ecru/off-white | D2: ='DMC Threads - By Number'!E6 -> 0
A3: Blanc^ | B3: White | D3: ='DMC Threads - By Number'!E7 -> 0
A4: White^ | B4: White | D4: ='DMC Threads - By Number'!E8 -> 0
A5: B5200 | B5: Snow White | D5: ='DMC Threads - By Number'!E9 -> 0
A6: 1 | B6: White Tin | D6: ='DMC Threads - By Number'!E10 -> 0
A7: 2 | B7: Tin | D7: ='DMC Threads - By Number'!E11 -> 0
A8: 3 | B8: Tin - Medium | D8: ='DMC Threads - By Number'!E12 -> 0
A9: 4 | B9: Tin - Dark | D9: ='DMC Threads - By Number'!E13 -> 0
A10: 5 | B10: Driftwood - Light | D10: ='DMC Threads - By Number'!E14 -> 0
A11: 6 | B11: Driftwood - Medium Light | D11: ='DMC Threads - By Number'!E15 -> 0
A12: 7 | B12: Driftwood | D12: ='DMC Threads - By Number'!E16 -> 0
A13: 8 | B13: Driftwood - Dark | D13: ='DMC Threads - By Number'!E17 -> 0
A14: 9 | B14: Cocoa - Very Dark | D14: ='DMC Threads - By Number'!E18 -> 0
A15: 10 | B15: Tender Green - Very Light | D15: ='DMC Threads - By Number'!E19 -> 0
A16: 11 | B16: Tender Green - Light | D16: ='DMC Threads - By Number'!E20 -> 0
A17: 12 | B17: Tender Green | D17: ='DMC Threads - By Number'!E21 -> 0
